<?xml version="1.0" encoding="utf-8"?>
<!-- This URDF was automatically created by SolidWorks to URDF Exporter! Originally created by Stephen Brawner (brawner@gmail.com) 
     Commit Version: 1.6.0-4-g7f85cfe  Build Version: 1.6.7995.38578
     For more information, please see http://wiki.ros.org/sw_urdf_exporter -->
<robot
  name="BaseMecanumURDF">
    
    <link name="odom">
      <visual>
        <origin xyz="0.0 0.0 0.0" rpy="0 0 0" />
        <geometry>
          <box size="0.1 0.1 0.1" />
        </geometry>
      </visual>

    <collision>
      <origin xyz="0.0 0.0 0.0" rpy="0 0 0" />
      <geometry>
        <box size="0.1 0.1 0.1" />
      </geometry>
    </collision>
  </link>

  <!-- Joint to connect odom and base_link -->
  <joint name="odom_to_base_link" type="fixed">
    <parent link="odom" />
    <child link="base_link" />
    <origin xyz="0.0 0.0 0.0" rpy="0 0 0" />
  </joint>
  <link
    name="base_link">
    <inertial>
      <origin
        xyz="-0.000222645088332468 0.0212706525268758 0.0478471444162569"
        rpy="0 0 0" />
      <mass
        value="1.14473814613392" />
      <inertia
        ixx="0.00406802532833408"
        ixy="-2.59714279495066E-07"
        ixz="-5.52464867857707E-08"
        iyy="0.00104621445375526"
        iyz="8.96167718563971E-05"
        izz="0.00444895141676235" />
    </inertial>
    <visual>
      <origin
        xyz="0 0 0"
        rpy="0 0 0" />
      <geometry>
        <mesh
          filename="package://gazebo_tools/meshes/robot/base_link.STL" />
      </geometry>
      <material
        name="">
        <color
          rgba="0.752941176470588 0.752941176470588 0.752941176470588 1" />
      </material>
    </visual>
    <collision>
      <origin
        xyz="0 0 0"
        rpy="0 0 0" />
      <geometry>
        <mesh
          filename="package://gazebo_tools/meshes/robot/base_link.STL" />
      </geometry>
    </collision>
  </link>
  <link
    name="FrontRight_wheel">
    <inertial>
      <origin
        xyz="-0.0200915998046353 -4.09353535379131E-05 -7.3187470010113E-05"
        rpy="0 0 0" />
      <mass
        value="0.0641393198112098" />
      <inertia
        ixx="1.05909175225007E-05"
        ixy="-2.65960923461101E-08"
        ixz="1.4884879064518E-08"
        iyy="9.22024127424863E-06"
        iyz="-3.32779596876557E-08"
        izz="9.1793540218031E-06" />
    </inertial>
    <visual>
      <origin xyz="0 0 0" rpy="0 1.5708 0" />
      <geometry>
        <cylinder radius="0.04" length="0.03" />
      </geometry>
      <material name="">
        <color rgba="0.752941176470588 0.752941176470588 0.752941176470588 1" />
      </material>
    </visual>
    <collision>
      <origin xyz="0 0 0" rpy="0 1.5708 0" />
      <geometry>
        <cylinder radius="0.04" length="0.03" />
      </geometry>
      <material name="">
        <color rgba="0.752941176470588 0.752941176470588 0.752941176470588 1" />
      </material>
    </collision>
  </link>
  <joint
    name="A_wheel"
    type="continuous">
    <origin
      xyz="-0.092408 -0.0225 0.0375"
      rpy="1.5773 0 0" />
    <parent
      link="base_link" />
    <child
      link="FrontRight_wheel" />
    <axis
      xyz="1 0 0" />
  </joint>
  <link
    name="A_r1">
    <inertial>
      <origin
        xyz="-0.0200916046432381 0.00815698765209493 -0.0288697688325274"
        rpy="0 0 0" />
      <mass
        value="0.00600569680327048" />
      <inertia
        ixx="4.16201839265504E-07"
        ixy="-2.33787813314613E-07"
        ixz="-6.6055406175231E-08"
        iyy="4.34162277016352E-07"
        iyz="-6.35668102139208E-08"
        izz="6.41181843474001E-07" />
    </inertial>
    <visual>
      <origin
        xyz="0 0 0"
        rpy="0 0 0" />
      <geometry>
        <mesh
          filename="package://gazebo_tools/meshes/robot/A_r1.STL" />
      </geometry>
      <material
        name="">
        <color
          rgba="0.792156862745098 0.819607843137255 0.933333333333333 1" />
      </material>
    </visual>
    <collision>
      <origin
        xyz="0 0 0"
        rpy="0 0 0" />
      <geometry>
        <mesh
          filename="package://gazebo_tools/meshes/robot/A_r1.STL" />
      </geometry>
    </collision>
  </link>
  <joint
    name="A1"
    type="continuous">
    <origin
      xyz="0 0 0"
      rpy="0 0 0" />
    <parent
      link="FrontRight_wheel" />
    <child
      link="A_r1" />
    <axis
      xyz="-0.70711 -0.68047 -0.19226" />
  </joint>
  <link
    name="A_r2">
    <inertial>
      <origin
        xyz="-0.0200916046432381 -0.0146461480299166 -0.0261818705956196"
        rpy="0 0 0" />
      <mass
        value="0.00600569680327048" />
      <inertia
        ixx="4.16201839265597E-07"
        ixy="-2.1202117379408E-07"
        ixz="1.18604722512999E-07"
        iyy="4.74105250031347E-07"
        iyz="1.03509783228825E-07"
        izz="6.01238870459196E-07" />
    </inertial>
    <visual>
      <origin
        xyz="0 0 0"
        rpy="0 0 0" />
      <geometry>
        <mesh
          filename="package://gazebo_tools/meshes/robot/A_r2.STL" />
      </geometry>
      <material
        name="">
        <color
          rgba="0.792156862745098 0.819607843137255 0.933333333333333 1" />
      </material>
    </visual>
    <collision>
      <origin
        xyz="0 0 0"
        rpy="0 0 0" />
      <geometry>
        <mesh
          filename="package://gazebo_tools/meshes/robot/A_r2.STL" />
      </geometry>
    </collision>
  </link>
  <joint
    name="A2"
    type="continuous">
    <origin
      xyz="0 0 0"
      rpy="0 0 0" />
    <parent
      link="FrontRight_wheel" />
    <child
      link="A_r2" />
    <axis
      xyz="-0.70711 -0.61711 0.34521" />
  </joint>
  <link
    name="A_r3">
    <inertial>
      <origin
        xyz="-0.0200916046432382 -0.0261818705956195 0.0146461480299167"
        rpy="0 0 0" />
      <mass
        value="0.00600569680327051" />
      <inertia
        ixx="4.16201839266206E-07"
        ixy="1.18604722512901E-07"
        ixz="2.12021173793902E-07"
        iyy="6.01238870459649E-07"
        iyz="-1.03509783228739E-07"
        izz="4.74105250031909E-07" />
    </inertial>
    <visual>
      <origin
        xyz="0 0 0"
        rpy="0 0 0" />
      <geometry>
        <mesh
          filename="package://gazebo_tools/meshes/robot/A_r3.STL" />
      </geometry>
      <material
        name="">
        <color
          rgba="0.792156862745098 0.819607843137255 0.933333333333333 1" />
      </material>
    </visual>
    <collision>
      <origin
        xyz="0 0 0"
        rpy="0 0 0" />
      <geometry>
        <mesh
          filename="package://gazebo_tools/meshes/robot/A_r3.STL" />
      </geometry>
    </collision>
  </link>
  <joint
    name="A3"
    type="continuous">
    <origin
      xyz="0 0 0"
      rpy="0 0 0" />
    <parent
      link="FrontRight_wheel" />
    <child
      link="A_r3" />
    <axis
      xyz="-0.70711 0.34521 0.61711" />
  </joint>
  <link
    name="A_r4">
    <inertial>
      <origin
        xyz="-0.0200916046432381 0.0146461480299168 0.0261818705956195"
        rpy="0 0 0" />
      <mass
        value="0.00600569680327057" />
      <inertia
        ixx="4.16201839266947E-07"
        ixy="2.12021173793702E-07"
        ixz="-1.1860472251279E-07"
        iyy="4.74105250032596E-07"
        iyz="1.03509783228641E-07"
        izz="6.01238870460215E-07" />
    </inertial>
    <visual>
      <origin
        xyz="0 0 0"
        rpy="0 0 0" />
      <geometry>
        <mesh
          filename="package://gazebo_tools/meshes/robot/A_r4.STL" />
      </geometry>
      <material
        name="">
        <color
          rgba="0.792156862745098 0.819607843137255 0.933333333333333 1" />
      </material>
    </visual>
    <collision>
      <origin
        xyz="0 0 0"
        rpy="0 0 0" />
      <geometry>
        <mesh
          filename="package://gazebo_tools/meshes/robot/A_r4.STL" />
      </geometry>
    </collision>
  </link>
  <joint
    name="A4"
    type="continuous">
    <origin
      xyz="0 0 0"
      rpy="0 0 0" />
    <parent
      link="FrontRight_wheel" />
    <child
      link="A_r4" />
    <axis
      xyz="-0.70711 0.61711 -0.34521" />
  </joint>
  <link
    name="A_r5">
    <inertial>
      <origin
        xyz="-0.0200916046432382 0.0261818705956195 -0.0146461480299169"
        rpy="0 0 0" />
      <mass
        value="0.00600569680327054" />
      <inertia
        ixx="4.16201839266459E-07"
        ixy="-1.18604722512857E-07"
        ixz="-2.1202117379382E-07"
        iyy="6.01238870459831E-07"
        iyz="-1.035097832287E-07"
        izz="4.74105250032141E-07" />
    </inertial>
    <visual>
      <origin
        xyz="0 0 0"
        rpy="0 0 0" />
      <geometry>
        <mesh
          filename="package://gazebo_tools/meshes/robot/A_r5.STL" />
      </geometry>
      <material
        name="">
        <color
          rgba="0.792156862745098 0.819607843137255 0.933333333333333 1" />
      </material>
    </visual>
    <collision>
      <origin
        xyz="0 0 0"
        rpy="0 0 0" />
      <geometry>
        <mesh
          filename="package://gazebo_tools/meshes/robot/A_r5.STL" />
      </geometry>
    </collision>
  </link>
  <joint
    name="A5"
    type="continuous">
    <origin
      xyz="0 0 0"
      rpy="0 0 0" />
    <parent
      link="FrontRight_wheel" />
    <child
      link="A_r5" />
    <axis
      xyz="-0.70711 -0.34521 -0.61711" />
  </joint>
  <link
    name="A_r6">
    <inertial>
      <origin
        xyz="-0.0200916046432382 -0.0288697688325274 -0.00815698765209482"
        rpy="0 0 0" />
      <mass
        value="0.00600569680327051" />
      <inertia
        ixx="4.16201839265985E-07"
        ixy="-6.60554061751913E-08"
        ixz="2.33787813314476E-07"
        iyy="6.41181843474351E-07"
        iyz="6.35668102138827E-08"
        izz="4.34162277016823E-07" />
    </inertial>
    <visual>
      <origin
        xyz="0 0 0"
        rpy="0 0 0" />
      <geometry>
        <mesh
          filename="package://gazebo_tools/meshes/robot/A_r6.STL" />
      </geometry>
      <material
        name="">
        <color
          rgba="0.792156862745098 0.819607843137255 0.933333333333333 1" />
      </material>
    </visual>
    <collision>
      <origin
        xyz="0 0 0"
        rpy="0 0 0" />
      <geometry>
        <mesh
          filename="package://gazebo_tools/meshes/robot/A_r6.STL" />
      </geometry>
    </collision>
  </link>
  <joint
    name="A6"
    type="continuous">
    <origin
      xyz="0 0 0"
      rpy="0 0 0" />
    <parent
      link="FrontRight_wheel" />
    <child
      link="A_r6" />
    <axis
      xyz="-0.70711 -0.19226 0.68047" />
  </joint>
  <link
    name="A_r7">
    <inertial>
      <origin
        xyz="-0.0200916046432382 -0.00815698765209471 0.0288697688325275"
        rpy="0 0 0" />
      <mass
        value="0.00600569680327051" />
      <inertia
        ixx="4.16201839265992E-07"
        ixy="2.33787813314482E-07"
        ixz="6.60554061751923E-08"
        iyy="4.34162277016829E-07"
        iyz="-6.35668102138837E-08"
        izz="6.41181843474364E-07" />
    </inertial>
    <visual>
      <origin
        xyz="0 0 0"
        rpy="0 0 0" />
      <geometry>
        <mesh
          filename="package://gazebo_tools/meshes/robot/A_r7.STL" />
      </geometry>
      <material
        name="">
        <color
          rgba="0.792156862745098 0.819607843137255 0.933333333333333 1" />
      </material>
    </visual>
    <collision>
      <origin
        xyz="0 0 0"
        rpy="0 0 0" />
      <geometry>
        <mesh
          filename="package://gazebo_tools/meshes/robot/A_r7.STL" />
      </geometry>
    </collision>
  </link>
  <joint
    name="A7"
    type="continuous">
    <origin
      xyz="0 0 0"
      rpy="0 0 0" />
    <parent
      link="FrontRight_wheel" />
    <child
      link="A_r7" />
    <axis
      xyz="-0.70711 0.68047 0.19226" />
  </joint>
  <link
    name="A_r8">
    <inertial>
      <origin
        xyz="-0.0200916046432381 0.0288697688325275 0.00815698765209463"
        rpy="0 0 0" />
      <mass
        value="0.00600569680327045" />
      <inertia
        ixx="4.16201839265042E-07"
        ixy="6.60554061752728E-08"
        ixz="-2.3378781331477E-07"
        iyy="6.41181843473691E-07"
        iyz="6.35668102139612E-08"
        izz="4.34162277015901E-07" />
    </inertial>
    <visual>
      <origin
        xyz="0 0 0"
        rpy="0 0 0" />
      <geometry>
        <mesh
          filename="package://gazebo_tools/meshes/robot/A_r8.STL" />
      </geometry>
      <material
        name="">
        <color
          rgba="0.792156862745098 0.819607843137255 0.933333333333333 1" />
      </material>
    </visual>
    <collision>
      <origin
        xyz="0 0 0"
        rpy="0 0 0" />
      <geometry>
        <mesh
          filename="package://gazebo_tools/meshes/robot/A_r8.STL" />
      </geometry>
    </collision>
  </link>
  <joint
    name="A8"
    type="continuous">
    <origin
      xyz="0 0 0"
      rpy="0 0 0" />
    <parent
      link="FrontRight_wheel" />
    <child
      link="A_r8" />
    <axis
      xyz="-0.70711 0.19226 -0.68047" />
  </joint>
  <link
    name="BackRight_wheel">
    <inertial>
      <origin
        xyz="-0.0212409681385203 8.38250730056805E-05 -3.64599689328671E-09"
        rpy="0 0 0" />
      <mass
        value="0.0641391844246041" />
      <inertia
        ixx="1.05908678603994E-05"
        ixy="-4.5508187669693E-12"
        ixz="3.04678274705248E-08"
        iyy="9.16071730151375E-06"
        iyz="4.54058049699005E-12"
        izz="9.23881987154415E-06" />
    </inertial>
    <visual>
      <origin xyz="0 0 0" rpy="0 1.5708 0" />
      <geometry>
        <cylinder radius="0.04" length="0.03" />
      </geometry>
      <material name="">
        <color rgba="0.752941176470588 0.752941176470588 0.752941176470588 1" />
      </material>
    </visual>
    <collision>
      <origin xyz="0 0 0" rpy="0 1.5708 0" />
      <geometry>
        <cylinder radius="0.04" length="0.03" />
      </geometry>
      <material name="">
        <color rgba="0.752941176470588 0.752941176470588 0.752941176470588 1" />
      </material>
    </collision>
  </link>
  <joint
    name="C_wheel"
    type="continuous">
    <origin
      xyz="-0.091259 0.0925 0.0375"
      rpy="1.5708 0 0" />
    <parent
      link="base_link" />
    <child
      link="BackRight_wheel" />
    <axis
      xyz="1 0 0" />
  </joint>
  <link
    name="C_r1">
    <inertial>
      <origin
        xyz="-0.021240971946251 0.03 2.22044604925031E-16"
        rpy="0 0 0" />
      <mass
        value="0.00600569680327048" />
      <inertia
        ixx="4.16201839265799E-07"
        ixy="2.14408505368392E-22"
        ixz="2.42940441959276E-07"
        iyy="6.59142281225074E-07"
        iyz="-2.14683357533442E-22"
        izz="4.16201839265798E-07" />
    </inertial>
    <visual>
      <origin
        xyz="0 0 0"
        rpy="0 0 0" />
      <geometry>
        <mesh
          filename="package://gazebo_tools/meshes/robot/C_r1.STL" />
      </geometry>
      <material
        name="">
        <color
          rgba="0.792156862745098 0.819607843137255 0.933333333333333 1" />
      </material>
    </visual>
    <collision>
      <origin
        xyz="0 0 0"
        rpy="0 0 0" />
      <geometry>
        <mesh
          filename="package://gazebo_tools/meshes/robot/C_r1.STL" />
      </geometry>
    </collision>
  </link>
  <joint
    name="C1"
    type="continuous">
    <origin
      xyz="0 0 0"
      rpy="0 0 0" />
    <parent
      link="BackRight_wheel" />
    <child
      link="C_r1" />
    <axis
      xyz="-0.70711 0 0.70711" />
  </joint>
  <link
    name="C_r2">
    <inertial>
      <origin
        xyz="-0.021240971946251 0.0212132034355966 -0.0212132034355963"
        rpy="0 0 0" />
      <mass
        value="0.00600569680327054" />
      <inertia
        ixx="4.16201839266474E-07"
        ixy="1.71784833933714E-07"
        ixz="1.71784833933714E-07"
        iyy="5.37672060246006E-07"
        iyz="-1.21470220979535E-07"
        izz="5.37672060246007E-07" />
    </inertial>
    <visual>
      <origin
        xyz="0 0 0"
        rpy="0 0 0" />
      <geometry>
        <mesh
          filename="package://gazebo_tools/meshes/robot/C_r2.STL" />
      </geometry>
      <material
        name="">
        <color
          rgba="0.792156862745098 0.819607843137255 0.933333333333333 1" />
      </material>
    </visual>
    <collision>
      <origin
        xyz="0 0 0"
        rpy="0 0 0" />
      <geometry>
        <mesh
          filename="package://gazebo_tools/meshes/robot/C_r2.STL" />
      </geometry>
    </collision>
  </link>
  <joint
    name="C2"
    type="continuous">
    <origin
      xyz="0 0 0"
      rpy="0 0 0" />
    <parent
      link="BackRight_wheel" />
    <child
      link="C_r2" />
    <axis
      xyz="-0.70711 0.5 0.5" />
  </joint>
  <link
    name="C_r3">
    <inertial>
      <origin
        xyz="-0.021240971946251 -0.0212132034355964 -0.0212132034355965"
        rpy="0 0 0" />
      <mass
        value="0.00600569680327051" />
      <inertia
        ixx="4.16201839265991E-07"
        ixy="1.71784833933814E-07"
        ixz="-1.71784833933816E-07"
        iyy="5.37672060245597E-07"
        iyz="1.21470220979606E-07"
        izz="5.37672060245594E-07" />
    </inertial>
    <visual>
      <origin
        xyz="0 0 0"
        rpy="0 0 0" />
      <geometry>
        <mesh
          filename="package://gazebo_tools/meshes/robot/C_r3.STL" />
      </geometry>
      <material
        name="">
        <color
          rgba="0.792156862745098 0.819607843137255 0.933333333333333 1" />
      </material>
    </visual>
    <collision>
      <origin
        xyz="0 0 0"
        rpy="0 0 0" />
      <geometry>
        <mesh
          filename="package://gazebo_tools/meshes/robot/C_r3.STL" />
      </geometry>
    </collision>
  </link>
  <joint
    name="C3"
    type="continuous">
    <origin
      xyz="0 0 0"
      rpy="0 0 0" />
    <parent
      link="BackRight_wheel" />
    <child
      link="C_r3" />
    <axis
      xyz="-0.70711 0.5 -0.5" />
  </joint>
  <link
    name="C_r4">
    <inertial>
      <origin
        xyz="-0.021240971946251 -0.0212132034355964 0.0212132034355965"
        rpy="0 0 0" />
      <mass
        value="0.00600569680327051" />
      <inertia
        ixx="4.16201839265998E-07"
        ixy="-1.71784833933815E-07"
        ixz="-1.71784833933812E-07"
        iyy="5.37672060245599E-07"
        iyz="-1.21470220979605E-07"
        izz="5.37672060245603E-07" />
    </inertial>
    <visual>
      <origin
        xyz="0 0 0"
        rpy="0 0 0" />
      <geometry>
        <mesh
          filename="package://gazebo_tools/meshes/robot/C_r4.STL" />
      </geometry>
      <material
        name="">
        <color
          rgba="0.792156862745098 0.819607843137255 0.933333333333333 1" />
      </material>
    </visual>
    <collision>
      <origin
        xyz="0 0 0"
        rpy="0 0 0" />
      <geometry>
        <mesh
          filename="package://gazebo_tools/meshes/robot/C_r4.STL" />
      </geometry>
    </collision>
  </link>
  <joint
    name="C4"
    type="continuous">
    <origin
      xyz="0 0 0"
      rpy="0 0 0" />
    <parent
      link="BackRight_wheel" />
    <child
      link="C_r4" />
    <axis
      xyz="-0.70711 -0.5 -0.5" />
  </joint>
  <link
    name="C_r5">
    <inertial>
      <origin
        xyz="-0.021240971946251 0.0212132034355965 0.0212132034355963"
        rpy="0 0 0" />
      <mass
        value="0.00600569680327051" />
      <inertia
        ixx="4.16201839265992E-07"
        ixy="-1.71784833933813E-07"
        ixz="1.71784833933817E-07"
        iyy="5.376720602456E-07"
        iyz="1.21470220979606E-07"
        izz="5.37672060245593E-07" />
    </inertial>
    <visual>
      <origin
        xyz="0 0 0"
        rpy="0 0 0" />
      <geometry>
        <mesh
          filename="package://gazebo_tools/meshes/robot/C_r5.STL" />
      </geometry>
      <material
        name="">
        <color
          rgba="0.792156862745098 0.819607843137255 0.933333333333333 1" />
      </material>
    </visual>
    <collision>
      <origin
        xyz="0 0 0"
        rpy="0 0 0" />
      <geometry>
        <mesh
          filename="package://gazebo_tools/meshes/robot/C_r5.STL" />
      </geometry>
    </collision>
  </link>
  <joint
    name="C5"
    type="continuous">
    <origin
      xyz="0 0 0"
      rpy="0 0 0" />
    <parent
      link="BackRight_wheel" />
    <child
      link="C_r5" />
    <axis
      xyz="-0.70711 -0.5 0.5" />
  </joint>
  <link
    name="C_r6">
    <inertial>
      <origin
        xyz="-0.021240971946251 1.04083408558608E-16 -0.03"
        rpy="0 0 0" />
      <mass
        value="0.00600569680327051" />
      <inertia
        ixx="4.16201839265991E-07"
        ixy="2.42940441959212E-07"
        ixz="-1.02626359182912E-21"
        iyy="4.16201839265989E-07"
        iyz="1.02534573638868E-21"
        izz="6.59142281225202E-07" />
    </inertial>
    <visual>
      <origin
        xyz="0 0 0"
        rpy="0 0 0" />
      <geometry>
        <mesh
          filename="package://gazebo_tools/meshes/robot/C_r6.STL" />
      </geometry>
      <material
        name="">
        <color
          rgba="0.792156862745098 0.819607843137255 0.933333333333333 1" />
      </material>
    </visual>
    <collision>
      <origin
        xyz="0 0 0"
        rpy="0 0 0" />
      <geometry>
        <mesh
          filename="package://gazebo_tools/meshes/robot/C_r6.STL" />
      </geometry>
    </collision>
  </link>
  <joint
    name="C6"
    type="continuous">
    <origin
      xyz="0 0 0"
      rpy="0 0 0" />
    <parent
      link="BackRight_wheel" />
    <child
      link="C_r6" />
    <axis
      xyz="-0.70711 0.70711 0" />
  </joint>
  <link
    name="C_r7">
    <inertial>
      <origin
        xyz="-0.021240971946251 -0.03 0"
        rpy="0 0 0" />
      <mass
        value="0.00600569680327051" />
      <inertia
        ixx="4.16201839265992E-07"
        ixy="-1.87799660501057E-21"
        ixz="-2.42940441959211E-07"
        iyy="6.59142281225203E-07"
        iyz="-1.87742125444641E-21"
        izz="4.16201839265991E-07" />
    </inertial>
    <visual>
      <origin
        xyz="0 0 0"
        rpy="0 0 0" />
      <geometry>
        <mesh
          filename="package://gazebo_tools/meshes/robot/C_r7.STL" />
      </geometry>
      <material
        name="">
        <color
          rgba="0.792156862745098 0.819607843137255 0.933333333333333 1" />
      </material>
    </visual>
    <collision>
      <origin
        xyz="0 0 0"
        rpy="0 0 0" />
      <geometry>
        <mesh
          filename="package://gazebo_tools/meshes/robot/C_r7.STL" />
      </geometry>
    </collision>
  </link>
  <joint
    name="C7"
    type="continuous">
    <origin
      xyz="0 0 0"
      rpy="0 0 0" />
    <parent
      link="BackRight_wheel" />
    <child
      link="C_r7" />
    <axis
      xyz="-0.70711 0 -0.70711" />
  </joint>
  <link
    name="C_r8">
    <inertial>
      <origin
        xyz="-0.021240971946251 1.11022302462516E-16 0.03"
        rpy="0 0 0" />
      <mass
        value="0.00600569680327048" />
      <inertia
        ixx="4.16201839265799E-07"
        ixy="-2.42940441959276E-07"
        ixz="2.73210804118429E-21"
        iyy="4.16201839265798E-07"
        iyz="2.7330024702074E-21"
        izz="6.59142281225074E-07" />
    </inertial>
    <visual>
      <origin
        xyz="0 0 0"
        rpy="0 0 0" />
      <geometry>
        <mesh
          filename="package://gazebo_tools/meshes/robot/C_r8.STL" />
      </geometry>
      <material
        name="">
        <color
          rgba="0.792156862745098 0.819607843137255 0.933333333333333 1" />
      </material>
    </visual>
    <collision>
      <origin
        xyz="0 0 0"
        rpy="0 0 0" />
      <geometry>
        <mesh
          filename="package://gazebo_tools/meshes/robot/C_r8.STL" />
      </geometry>
    </collision>
  </link>
  <joint
    name="C8"
    type="continuous">
    <origin
      xyz="0 0 0"
      rpy="0 0 0" />
    <parent
      link="BackRight_wheel" />
    <child
      link="C_r8" />
    <axis
      xyz="-0.70711 -0.70711 0" />
  </joint>
  <link
    name="FrontLeft_wheel">
    <inertial>
      <origin
        xyz="0.0212409757539813 8.38250730056944E-05 -3.64599686206168E-09"
        rpy="0 0 0" />
      <mass
        value="0.0641391844246042" />
      <inertia
        ixx="1.0590867860399E-05"
        ixy="-4.5508186856012E-12"
        ixz="3.04678274704807E-08"
        iyy="9.1607173015134E-06"
        iyz="4.54058043391187E-12"
        izz="9.23881987154381E-06" />
    </inertial>
    <visual>
      <origin xyz="0 0 0" rpy="0 1.5708 0" />
      <geometry>
        <cylinder radius="0.04" length="0.03" />
      </geometry>
      <material name="">
        <color rgba="0.752941176470588 0.752941176470588 0.752941176470588 1" />
      </material>
    </visual>
    <collision>
      <origin xyz="1 0 0" rpy="0 0 0" />
      <geometry>
        <cylinder radius="0.04" length="0.04" />
      </geometry>
      <material name="">
        <color rgba="0.752941176470588 0.752941176470588 0.752941176470588 1" />
      </material>
    </collision>
  </link>
  <joint
    name="B_wheel"
    type="continuous">
    <origin
      xyz="0.0912590280537492 -0.0224999999999999 0.0374999999999991"
      rpy="1.5707963267949 0 0" />
    <parent
      link="base_link" />
    <child
      link="FrontLeft_wheel" />
    <axis
      xyz="1 0 0" />
  </joint>
  <link
    name="B_r1">
    <inertial>
      <origin
        xyz="0.0212409719462505 0.03 2.08166817117217E-16"
        rpy="0 0 0" />
      <mass
        value="0.00600569680327051" />
      <inertia
        ixx="4.16201839265992E-07"
        ixy="2.16330801622234E-22"
        ixz="2.42940441959211E-07"
        iyy="6.59142281225203E-07"
        iyz="-2.17058775491244E-22"
        izz="4.16201839265991E-07" />
    </inertial>
    <visual>
      <origin
        xyz="0 0 0"
        rpy="0 0 0" />
      <geometry>
        <mesh
          filename="package://gazebo_tools/meshes/robot/B_r1.STL" />
      </geometry>
      <material
        name="">
        <color
          rgba="0.792156862745098 0.819607843137255 0.933333333333333 1" />
      </material>
    </visual>
    <collision>
      <origin
        xyz="0 0 0"
        rpy="0 0 0" />
      <geometry>
        <mesh
          filename="package://gazebo_tools/meshes/robot/B_r1.STL" />
      </geometry>
    </collision>
  </link>
  <joint
    name="B1"
    type="continuous">
    <origin
      xyz="0 0 0"
      rpy="0 0 0" />
    <parent
      link="FrontLeft_wheel" />
    <child
      link="B_r1" />
    <axis
      xyz="-0.70711 0.5 -0.5" />
  </joint>
  <link
    name="B_r2">
    <inertial>
      <origin
        xyz="0.0212409719462506 0.0212132034355965 -0.0212132034355963"
        rpy="0 0 0" />
      <mass
        value="0.00600569680327051" />
      <inertia
        ixx="4.16201839266065E-07"
        ixy="1.71784833933798E-07"
        ixz="1.71784833933798E-07"
        iyy="5.37672060245656E-07"
        iyz="-1.21470220979594E-07"
        izz="5.37672060245657E-07" />
    </inertial>
    <visual>
      <origin
        xyz="0 0 0"
        rpy="0 0 0" />
      <geometry>
        <mesh
          filename="package://gazebo_tools/meshes/robot/B_r2.STL" />
      </geometry>
      <material
        name="">
        <color
          rgba="0.792156862745098 0.819607843137255 0.933333333333333 1" />
      </material>
    </visual>
    <collision>
      <origin
        xyz="0 0 0"
        rpy="0 0 0" />
      <geometry>
        <mesh
          filename="package://gazebo_tools/meshes/robot/B_r2.STL" />
      </geometry>
    </collision>
  </link>
  <joint
    name="B2"
    type="continuous">
    <origin
      xyz="0 0 0"
      rpy="0 0 0" />
    <parent
      link="FrontLeft_wheel" />
    <child
      link="B_r2" />
    <axis
      xyz="-0.70711 0 -0.70711" />
  </joint>
  <link
    name="B_r3">
    <inertial>
      <origin
        xyz="0.0212409719462506 -0.0212132034355964 -0.0212132034355965"
        rpy="0 0 0" />
      <mass
        value="0.00600569680327051" />
      <inertia
        ixx="4.16201839265991E-07"
        ixy="1.71784833933814E-07"
        ixz="-1.71784833933816E-07"
        iyy="5.37672060245597E-07"
        iyz="1.21470220979606E-07"
        izz="5.37672060245594E-07" />
    </inertial>
    <visual>
      <origin
        xyz="0 0 0"
        rpy="0 0 0" />
      <geometry>
        <mesh
          filename="package://gazebo_tools/meshes/robot/B_r3.STL" />
      </geometry>
      <material
        name="">
        <color
          rgba="0.792156862745098 0.819607843137255 0.933333333333333 1" />
      </material>
    </visual>
    <collision>
      <origin
        xyz="0 0 0"
        rpy="0 0 0" />
      <geometry>
        <mesh
          filename="package://gazebo_tools/meshes/robot/B_r3.STL" />
      </geometry>
    </collision>
  </link>
  <joint
    name="B3"
    type="continuous">
    <origin
      xyz="0 0 0"
      rpy="0 0 0" />
    <parent
      link="FrontLeft_wheel" />
    <child
      link="B_r3" />
    <axis
      xyz="-0.707106781186546 -0.707106781186549 0" />
  </joint>
  <link
    name="B_r4">
    <inertial>
      <origin
        xyz="0.0212409719462506 -0.0212132034355964 0.0212132034355965"
        rpy="0 0 0" />
      <mass
        value="0.00600569680327051" />
      <inertia
        ixx="4.16201839265992E-07"
        ixy="-1.71784833933817E-07"
        ixz="-1.71784833933813E-07"
        iyy="5.37672060245594E-07"
        iyz="-1.21470220979606E-07"
        izz="5.37672060245598E-07" />
    </inertial>
    <visual>
      <origin
        xyz="0 0 0"
        rpy="0 0 0" />
      <geometry>
        <mesh
          filename="package://gazebo_tools/meshes/robot/B_r4.STL" />
      </geometry>
      <material
        name="">
        <color
          rgba="0.792156862745098 0.819607843137255 0.933333333333333 1" />
      </material>
    </visual>
    <collision>
      <origin
        xyz="0 0 0"
        rpy="0 0 0" />
      <geometry>
        <mesh
          filename="package://gazebo_tools/meshes/robot/B_r4.STL" />
      </geometry>
    </collision>
  </link>
  <joint
    name="B4"
    type="continuous">
    <origin
      xyz="0 0 0"
      rpy="0 0 0" />
    <parent
      link="FrontLeft_wheel" />
    <child
      link="B_r4" />
    <axis
      xyz="-0.70711 0 0.70711" />
  </joint>
  <link
    name="B_r5">
    <inertial>
      <origin
        xyz="0.0212409719462506 0.0212132034355965 0.0212132034355963"
        rpy="0 0 0" />
      <mass
        value="0.00600569680327051" />
      <inertia
        ixx="4.16201839265991E-07"
        ixy="-1.71784833933813E-07"
        ixz="1.71784833933818E-07"
        iyy="5.37672060245599E-07"
        iyz="1.21470220979606E-07"
        izz="5.37672060245593E-07" />
    </inertial>
    <visual>
      <origin
        xyz="0 0 0"
        rpy="0 0 0" />
      <geometry>
        <mesh
          filename="package://gazebo_tools/meshes/robot/B_r5.STL" />
      </geometry>
      <material
        name="">
        <color
          rgba="0.792156862745098 0.819607843137255 0.933333333333333 1" />
      </material>
    </visual>
    <collision>
      <origin
        xyz="0 0 0"
        rpy="0 0 0" />
      <geometry>
        <mesh
          filename="package://gazebo_tools/meshes/robot/B_r5.STL" />
      </geometry>
    </collision>
  </link>
  <joint
    name="B5"
    type="continuous">
    <origin
      xyz="0 0 0"
      rpy="0 0 0" />
    <parent
      link="FrontLeft_wheel" />
    <child
      link="B_r5" />
    <axis
      xyz="-0.70711 0.70711 0" />
  </joint>
  <link
    name="B_r6">
    <inertial>
      <origin
        xyz="0.0212409719462505 1.04083408558608E-16 -0.03"
        rpy="0 0 0" />
      <mass
        value="0.00600569680327051" />
      <inertia
        ixx="4.16201839265991E-07"
        ixy="2.42940441959212E-07"
        ixz="-1.03197221168256E-21"
        iyy="4.16201839265989E-07"
        iyz="1.02776461694073E-21"
        izz="6.59142281225202E-07" />
    </inertial>
    <visual>
      <origin
        xyz="0 0 0"
        rpy="0 0 0" />
      <geometry>
        <mesh
          filename="package://gazebo_tools/meshes/robot/B_r6.STL" />
      </geometry>
      <material
        name="">
        <color
          rgba="0.792156862745098 0.819607843137255 0.933333333333333 1" />
      </material>
    </visual>
    <collision>
      <origin
        xyz="0 0 0"
        rpy="0 0 0" />
      <geometry>
        <mesh
          filename="package://gazebo_tools/meshes/robot/B_r6.STL" />
      </geometry>
    </collision>
  </link>
  <joint
    name="B6"
    type="continuous">
    <origin
      xyz="0 0 0"
      rpy="0 0 0" />
    <parent
      link="FrontLeft_wheel" />
    <child
      link="B_r6" />
    <axis
      xyz="-0.70711 -0.5 -0.5" />
  </joint>
  <link
    name="B_r7">
    <inertial>
      <origin
        xyz="0.0212409719462505 -0.03 0"
        rpy="0 0 0" />
      <mass
        value="0.00600569680327048" />
      <inertia
        ixx="4.16201839265799E-07"
        ixy="-1.87759084101227E-21"
        ixz="-2.42940441959275E-07"
        iyy="6.59142281225074E-07"
        iyz="-1.87444897680514E-21"
        izz="4.16201839265798E-07" />
    </inertial>
    <visual>
      <origin
        xyz="0 0 0"
        rpy="0 0 0" />
      <geometry>
        <mesh
          filename="package://gazebo_tools/meshes/robot/B_r7.STL" />
      </geometry>
      <material
        name="">
        <color
          rgba="0.792156862745098 0.819607843137255 0.933333333333333 1" />
      </material>
    </visual>
    <collision>
      <origin
        xyz="0 0 0"
        rpy="0 0 0" />
      <geometry>
        <mesh
          filename="package://gazebo_tools/meshes/robot/B_r7.STL" />
      </geometry>
    </collision>
  </link>
  <joint
    name="B7"
    type="continuous">
    <origin
      xyz="0 0 0"
      rpy="0 0 0" />
    <parent
      link="FrontLeft_wheel" />
    <child
      link="B_r7" />
    <axis
      xyz="-0.70711 -0.5 0.5" />
  </joint>
  <link
    name="B_r8">
    <inertial>
      <origin
        xyz="0.0212409719462505 1.04083408558608E-16 0.03"
        rpy="0 0 0" />
      <mass
        value="0.00600569680327048" />
      <inertia
        ixx="4.16201839265799E-07"
        ixy="-2.42940441959276E-07"
        ixz="2.70188040590916E-21"
        iyy="4.16201839265798E-07"
        iyz="2.70044586510457E-21"
        izz="6.59142281225074E-07" />
    </inertial>
    <visual>
      <origin
        xyz="0 0 0"
        rpy="0 0 0" />
      <geometry>
        <mesh
          filename="package://gazebo_tools/meshes/robot/B_r8.STL" />
      </geometry>
      <material
        name="">
        <color
          rgba="0.792156862745098 0.819607843137255 0.933333333333333 1" />
      </material>
    </visual>
    <collision>
      <origin
        xyz="0 0 0"
        rpy="0 0 0" />
      <geometry>
        <mesh
          filename="package://gazebo_tools/meshes/robot/B_r8.STL" />
      </geometry>
    </collision>
  </link>
  <joint
    name="B8"
    type="continuous">
    <origin
      xyz="0 0 0"
      rpy="0 0 0" />
    <parent
      link="FrontLeft_wheel" />
    <child
      link="B_r8" />
    <axis
      xyz="-0.70711 0.5 0.5" />
  </joint>
  <link
    name="BackLeft_wheel">
    <inertial>
      <origin
        xyz="0.0200916086706487 8.38563871495487E-05 4.20182770521915E-09"
        rpy="0 0 0" />
      <mass
        value="0.0641393148045686" />
      <inertia
        ixx="1.05909155191193E-05"
        ixy="-5.23192425961109E-12"
        ixz="-3.04774565518244E-08"
        iyy="9.16074049105945E-06"
        iyz="-5.21448564261971E-12"
        izz="9.23885155862502E-06" />
    </inertial>
    <visual>
      <origin xyz="0 0 0" rpy="0 1.5708 0" />
      <geometry>
        <cylinder radius="0.04" length="0.03" />
      </geometry>
      <material name="">
        <color rgba="0.752941176470588 0.752941176470588 0.752941176470588 1" />
      </material>
    </visual>
    <collision>
      <origin xyz="0 0 0" rpy="0 1.5708 0" />
      <geometry>
        <cylinder radius="0.04" length="0.03" />
      </geometry>
      <material name="">
        <color rgba="0.752941176470588 0.752941176470588 0.752941176470588 1" />
      </material>
    </collision>
  </link>
  <joint
    name="D_wheel"
    type="continuous">
    <origin
      xyz="0.092408395356762 0.0925000000000001 0.0374999999999991"
      rpy="1.5707963267949 0 0" />
    <parent
      link="base_link" />
    <child
      link="BackLeft_wheel" />
    <axis
      xyz="1 0 0" />
  </joint>
  <link
    name="D_r1">
    <inertial>
      <origin
        xyz="0.0200916046432377 0.0212132034355968 0.021213203435596"
        rpy="0 0 0" />
      <mass
        value="0.00600569680327051" />
      <inertia
        ixx="4.16201839265991E-07"
        ixy="1.71784833933813E-07"
        ixz="-1.71784833933817E-07"
        iyy="5.37672060245598E-07"
        iyz="1.21470220979606E-07"
        izz="5.37672060245592E-07" />
    </inertial>
    <visual>
      <origin
        xyz="0 0 0"
        rpy="0 0 0" />
      <geometry>
        <mesh
          filename="package://gazebo_tools/meshes/robot/D_r1.STL" />
      </geometry>
      <material
        name="">
        <color
          rgba="0.792156862745098 0.819607843137255 0.933333333333333 1" />
      </material>
    </visual>
    <collision>
      <origin
        xyz="0 0 0"
        rpy="0 0 0" />
      <geometry>
        <mesh
          filename="package://gazebo_tools/meshes/robot/D_r1.STL" />
      </geometry>
    </collision>
  </link>
  <joint
    name="D1"
    type="continuous">
    <origin
      xyz="0 0 0"
      rpy="0 0 0" />
    <parent
      link="BackLeft_wheel" />
    <child
      link="D_r1" />
    <axis
      xyz="-0.70711 0 0.70711" />
  </joint>
  <link
    name="D_r2">
    <inertial>
      <origin
        xyz="0.0200916046432377 0.03 -2.22044604925031E-16"
        rpy="0 0 0" />
      <mass
        value="0.00600569680327048" />
      <inertia
        ixx="4.16201839265597E-07"
        ixy="-6.98109242597207E-23"
        ixz="-2.42940441959352E-07"
        iyy="6.59142281224948E-07"
        iyz="-6.25996436510468E-23"
        izz="4.16201839265596E-07" />
    </inertial>
    <visual>
      <origin
        xyz="0 0 0"
        rpy="0 0 0" />
      <geometry>
        <mesh
          filename="package://gazebo_tools/meshes/robot/D_r2.STL" />
      </geometry>
      <material
        name="">
        <color
          rgba="0.792156862745098 0.819607843137255 0.933333333333333 1" />
      </material>
    </visual>
    <collision>
      <origin
        xyz="0 0 0"
        rpy="0 0 0" />
      <geometry>
        <mesh
          filename="package://gazebo_tools/meshes/robot/D_r2.STL" />
      </geometry>
    </collision>
  </link>
  <joint
    name="D2"
    type="continuous">
    <origin
      xyz="0 0 0"
      rpy="0 0 0" />
    <parent
      link="BackLeft_wheel" />
    <child
      link="D_r2" />
    <axis
      xyz="-0.70711 0.5 0.5" />
  </joint>
  <link
    name="D_r3">
    <inertial>
      <origin
        xyz="0.0200916046432377 -3.12250225675825E-16 -0.03"
        rpy="0 0 0" />
      <mass
        value="0.00600569680327048" />
      <inertia
        ixx="4.16201839265597E-07"
        ixy="-2.42940441959352E-07"
        ixz="9.91843007856264E-22"
        iyy="4.16201839265596E-07"
        iyz="9.7923511126621E-22"
        izz="6.59142281224948E-07" />
    </inertial>
    <visual>
      <origin
        xyz="0 0 0"
        rpy="0 0 0" />
      <geometry>
        <mesh
          filename="package://gazebo_tools/meshes/robot/D_r3.STL" />
      </geometry>
      <material
        name="">
        <color
          rgba="0.792156862745098 0.819607843137255 0.933333333333333 1" />
      </material>
    </visual>
    <collision>
      <origin
        xyz="0 0 0"
        rpy="0 0 0" />
      <geometry>
        <mesh
          filename="package://gazebo_tools/meshes/robot/D_r3.STL" />
      </geometry>
    </collision>
  </link>
  <joint
    name="D3"
    type="continuous">
    <origin
      xyz="0 0 0"
      rpy="0 0 0" />
    <parent
      link="BackLeft_wheel" />
    <child
      link="D_r3" />
    <axis
      xyz="-0.707106781186546 0.499999999999998 -0.500000000000004" />
  </joint>
  <link
    name="D_r4">
    <inertial>
      <origin
        xyz="0.0200916046432377 -0.03 4.16333634234434E-16"
        rpy="0 0 0" />
      <mass
        value="0.00600569680327051" />
      <inertia
        ixx="4.16201839265991E-07"
        ixy="1.81186000626509E-21"
        ixz="2.42940441959211E-07"
        iyy="6.59142281225202E-07"
        iyz="-1.8007555673878E-21"
        izz="4.16201839265989E-07" />
    </inertial>
    <visual>
      <origin
        xyz="0 0 0"
        rpy="0 0 0" />
      <geometry>
        <mesh
          filename="package://gazebo_tools/meshes/robot/D_r4.STL" />
      </geometry>
      <material
        name="">
        <color
          rgba="0.792156862745098 0.819607843137255 0.933333333333333 1" />
      </material>
    </visual>
    <collision>
      <origin
        xyz="0 0 0"
        rpy="0 0 0" />
      <geometry>
        <mesh
          filename="package://gazebo_tools/meshes/robot/D_r4.STL" />
      </geometry>
    </collision>
  </link>
  <joint
    name="D4"
    type="continuous">
    <origin
      xyz="0 0 0"
      rpy="0 0 0" />
    <parent
      link="BackLeft_wheel" />
    <child
      link="D_r4" />
    <axis
      xyz="-0.70711 -0.5 -0.5" />
  </joint>
  <link
    name="D_r5">
    <inertial>
      <origin
        xyz="0.0200916046432377 5.20417042793042E-16 0.03"
        rpy="0 0 0" />
      <mass
        value="0.00600569680327048" />
      <inertia
        ixx="4.16201839265597E-07"
        ixy="2.42940441959352E-07"
        ixz="-2.64165484065035E-21"
        iyy="4.16201839265596E-07"
        iyz="2.62319720435548E-21"
        izz="6.59142281224949E-07" />
    </inertial>
    <visual>
      <origin
        xyz="0 0 0"
        rpy="0 0 0" />
      <geometry>
        <mesh
          filename="package://gazebo_tools/meshes/robot/D_r5.STL" />
      </geometry>
      <material
        name="">
        <color
          rgba="0.792156862745098 0.819607843137255 0.933333333333333 1" />
      </material>
    </visual>
    <collision>
      <origin
        xyz="0 0 0"
        rpy="0 0 0" />
      <geometry>
        <mesh
          filename="package://gazebo_tools/meshes/robot/D_r5.STL" />
      </geometry>
    </collision>
  </link>
  <joint
    name="D5"
    type="continuous">
    <origin
      xyz="0 0 0"
      rpy="0 0 0" />
    <parent
      link="BackLeft_wheel" />
    <child
      link="D_r5" />
    <axis
      xyz="-0.70711 -0.5 0.5" />
  </joint>
  <link
    name="D_r6">
    <inertial>
      <origin
        xyz="0.0200916046432377 0.0212132034355959 -0.0212132034355969"
        rpy="0 0 0" />
      <mass
        value="0.00600569680327051" />
      <inertia
        ixx="4.16201839265992E-07"
        ixy="-1.71784833933818E-07"
        ixz="-1.71784833933812E-07"
        iyy="5.37672060245593E-07"
        iyz="-1.21470220979606E-07"
        izz="5.376720602456E-07" />
    </inertial>
    <visual>
      <origin
        xyz="0 0 0"
        rpy="0 0 0" />
      <geometry>
        <mesh
          filename="package://gazebo_tools/meshes/robot/D_r6.STL" />
      </geometry>
      <material
        name="">
        <color
          rgba="0.792156862745098 0.819607843137255 0.933333333333333 1" />
      </material>
    </visual>
    <collision>
      <origin
        xyz="0 0 0"
        rpy="0 0 0" />
      <geometry>
        <mesh
          filename="package://gazebo_tools/meshes/robot/D_r6.STL" />
      </geometry>
    </collision>
  </link>
  <joint
    name="D6"
    type="continuous">
    <origin
      xyz="0 0 0"
      rpy="0 0 0" />
    <parent
      link="BackLeft_wheel" />
    <child
      link="D_r6" />
    <axis
      xyz="-0.70711 0.70711 0" />
  </joint>
  <link
    name="D_r7">
    <inertial>
      <origin
        xyz="0.0200916046432377 -0.021213203435597 -0.0212132034355959"
        rpy="0 0 0" />
      <mass
        value="0.00600569680327051" />
      <inertia
        ixx="4.16201839265997E-07"
        ixy="-1.7178483393381E-07"
        ixz="1.71784833933817E-07"
        iyy="5.37672060245605E-07"
        iyz="1.21470220979605E-07"
        izz="5.37672060245596E-07" />
    </inertial>
    <visual>
      <origin
        xyz="0 0 0"
        rpy="0 0 0" />
      <geometry>
        <mesh
          filename="package://gazebo_tools/meshes/robot/D_r7.STL" />
      </geometry>
      <material
        name="">
        <color
          rgba="0.792156862745098 0.819607843137255 0.933333333333333 1" />
      </material>
    </visual>
    <collision>
      <origin
        xyz="0 0 0"
        rpy="0 0 0" />
      <geometry>
        <mesh
          filename="package://gazebo_tools/meshes/robot/D_r7.STL" />
      </geometry>
    </collision>
  </link>
  <joint
    name="D7"
    type="continuous">
    <origin
      xyz="0 0 0"
      rpy="0 0 0" />
    <parent
      link="BackLeft_wheel" />
    <child
      link="D_r7" />
    <axis
      xyz="-0.70711 0 -0.70711" />
  </joint>
  <link
    name="D_r8">
    <inertial>
      <origin
        xyz="0.0200916046432377 -0.0212132034355958 0.021213203435597"
        rpy="0 0 0" />
      <mass
        value="0.00600569680327051" />
      <inertia
        ixx="4.16201839265986E-07"
        ixy="1.71784833933814E-07"
        ixz="1.71784833933807E-07"
        iyy="5.37672060245581E-07"
        iyz="-1.21470220979603E-07"
        izz="5.37672060245592E-07" />
    </inertial>
    <visual>
      <origin
        xyz="0 0 0"
        rpy="0 0 0" />
      <geometry>
        <mesh
          filename="package://gazebo_tools/meshes/robot/D_r8.STL" />
      </geometry>
      <material
        name="">
        <color
          rgba="0.792156862745098 0.819607843137255 0.933333333333333 1" />
      </material>
    </visual>
    <collision>
      <origin
        xyz="0 0 0"
        rpy="0 0 0" />
      <geometry>
        <mesh
          filename="package://gazebo_tools/meshes/robot/D_r8.STL" />
      </geometry>
    </collision>
  </link>
  <joint
    name="D8"
    type="continuous">
    <origin
      xyz="0 0 0"
      rpy="0 0 0" />
    <parent
      link="BackLeft_wheel" />
    <child
      link="D_r8" />
    <axis
      xyz="-0.70711 -0.70711 0" />
  </joint>


<!-- Stage URDF -->
<link
    name="map">
    <inertial>
      <origin
        xyz="2.0 0.0 0.0"
        rpy="0 0 0" />
      <mass
        value="0" />
      <inertia
        ixx="0.0"
        ixy="0.0"
        ixz="0.0"
        iyy="0.0"
        iyz="0.0"
        izz="0.0" />
    </inertial>
    <visual>
      <origin
        xyz="2.0 0.0 0.0"
        rpy="0 0 0" />
      <geometry>
        <mesh
          filename="package://gazebo_tools/meshes/stage/base_link.STL" />
      </geometry>
      <material
        name="">
        <color
          rgba="0.752941176470588 0.752941176470588 0.752941176470588 1" />
      </material>
    </visual>
    <collision>
      <origin
        xyz="2.0 0.0 0.0"
        rpy="0 0 0" />
      <geometry>
        <mesh
          filename="package://gazebo_tools/meshes/stage/base_link.STL" />
      </geometry>
    </collision>
  </link>

  <!-- Joint to link world_link to odom -->
  <joint name="world_to_odom" type="fixed">
    <parent link="map"/>
    <child link="odom"/>
    <origin xyz="0 0 0" rpy="0 0 0" />
  </joint>
  
</robot>